<?xml version="1.0" ?>
<!-- =================================================================================== -->
<!-- |    This document was autogenerated by xacro from pioneer3at.urdf.xacro          | -->
<!-- |    EDITING THIS FILE BY HAND IS NOT RECOMMENDED                                 | -->
<!-- =================================================================================== -->
<robot name="pioneer3at" xmlns:controller="http://playerstage.sourceforge.net/gazebo/xmlschema/#controller" xmlns:interface="http://playerstage.sourceforge.net/gazebo/xmlschema/#interface" xmlns:sensor="http://playerstage.sourceforge.net/gazebo/xmlschema/#sensor" xmlns:xacro="http://ros.org/wiki/xacro">
  <!-- Chassis -->
  <link name="base_link">
    <!--  For pointers on inertial and gazebo-related parameters see
		       * http://wiki.ros.org/urdf/Tutorials/Adding%20Physical%20and%20Collision%20Properties%20to%20a%20URDF%20Model
                       * http://answers.gazebosim.org/question/4372/the-inertia-matrix-explained/
		       * http://gazebosim.org/tutorials?tut=inertia&cat=build_robot, and 
                       * http://gazebosim.org/tutorials/?tut=ros_urdf
                       * http://en.wikipedia.org/wiki/List_of_moment_of_inertia_tensors  
                -->
    <inertial>
      <mass value="21.5"/>
      <!-- P3AT 18.6kg plus three batteries @ 2.4kg each  minus four wheels @ 1.4 kg ea and top plate @ 0.1 kg-->
      <origin xyz=" -0.1 0 0.177"/>
      <inertia ixx="0.3338" ixy="0.0" ixz="0.0" iyy="0.4783" iyz="0.0" izz="0.3338"/>
    </inertial>
    <visual>
      <origin rpy="0 0 0" xyz="0 0 0.177"/>
      <geometry name="pioneer_geom">
        <mesh filename="package://amr_robots_description/meshes/p3at_meshes/chassis.stl"/>
      </geometry>
      <material name="ChassisRed">
        <color rgba="0.851 0.0 0.0 1.0"/>
      </material>
    </visual>
    <collision>
      <origin rpy="0 0 0" xyz="0 0 0.177"/>
      <geometry>
        <mesh filename="package://amr_robots_description/meshes/p3at_meshes/chassis.stl"/>
      </geometry>
    </collision>
  </link>
  <gazebo reference="base_link">
    <material value="Gazebo/Red"/>
  </gazebo>
  <!-- Top -->
  <link name="top_plate">
    <inertial>
      <mass value="0.1"/>
      <origin xyz="-0.025 0 -0.223"/>
      <inertia ixx="1.0" ixy="0.0" ixz="0.0" iyy="1.0" iyz="0.0" izz="1.0"/>
    </inertial>
    <visual>
      <origin rpy="0 0 0" xyz="0 0 0"/>
      <geometry name="pioneer_geom">
        <mesh filename="package://amr_robots_description/meshes/p3at_meshes/top.stl"/>
      </geometry>
      <material name="TopBlack">
        <color rgba="0.038 0.038 0.038 1.0"/>
      </material>
    </visual>
  </link>
  <gazebo reference="top_plate">
    <material>Gazebo/Black</material>
  </gazebo>
  <joint name="base_top_joint" type="fixed">
    <origin rpy="0 0 0" xyz="0.003 0 0.274"/>
    <parent link="base_link"/>
    <child link="top_plate"/>
  </joint>
  <!-- Front + Back Sonar -->
  <link name="front_sonar">
    <inertial>
      <mass value="0.1"/>
      <origin xyz="0 0 0"/>
      <inertia ixx="1.0" ixy="0.0" ixz="0.0" iyy="1.0" iyz="0.0" izz="1.0"/>
    </inertial>
    <visual>
      <origin rpy="0 0 0" xyz="0 0 0"/>
      <geometry name="pioneer_geom">
        <mesh filename="package://amr_robots_description/meshes/p3at_meshes/front_sonar.stl"/>
      </geometry>
      <material name="SonarYellow">
        <color rgba="0.715 0.583 0.210 1.0"/>
      </material>
    </visual>
  </link>
  <gazebo reference="front_sonar">
    <material value="Gazebo/Yellow"/>
  </gazebo>
  <joint name="base_front_joint" type="fixed">
    <origin rpy="0 0 0" xyz="0.193 0 0.25"/>
    <parent link="base_link"/>
    <child link="front_sonar"/>
  </joint>
  <link name="back_sonar">
    <inertial>
      <mass value="0.1"/>
      <origin xyz="0 0 0"/>
      <inertia ixx="1.0" ixy="0.0" ixz="0.0" iyy="1.0" iyz="0.0" izz="1.0"/>
    </inertial>
    <visual>
      <origin rpy="0 0 0" xyz="0 0 0"/>
      <geometry name="pioneer_geom">
        <mesh filename="package://amr_robots_description/meshes/p3at_meshes/back_sonar.stl"/>
      </geometry>
      <material name="SonarYellow">
        <color rgba="0.715 0.583 0.210 1.0"/>
      </material>
    </visual>
  </link>
  <gazebo reference="back_sonar">
    <material value="Gazebo/Yellow"/>
  </gazebo>
  <joint name="base_back_joint" type="fixed">
    <origin rpy="0 0 0" xyz="-0.187 0 0.247"/>
    <parent link="base_link"/>
    <child link="back_sonar"/>
  </joint>
  
  <link name="velodyne">
    <inertial>
      <mass value="0.01"/>
      <origin xyz="0 0 0"/>
      <inertia ixx="1e-7" ixy="0.0" ixz="0.0" iyy="1e-7" iyz="0.0" izz="1e-7"/>
    </inertial>
    <visual>
        <geometry>
          <mesh filename="package://velodyne_description/meshes/VLP16_base_1.dae" />
        </geometry>
      </visual>
      <visual>
        <geometry>
          <mesh filename="package://velodyne_description/meshes/VLP16_base_2.dae" />
        </geometry>
      </visual>
  </link>
  <gazebo reference="velodyne">
    <sensor name="sensor_velodyne" type="ray">
	<visualize>0</visualize>
	<update_rate>10</update_rate>
	<pose> 0 0 0 0 0 0 </pose>
	<plugin name="ros_velodyne" filename="libgazebo_ros_velodyne_laser.so">
          <topicName>/points</topicName>
          <frameName>velodyne</frameName>
	</plugin>
	<ray>
	  <scan>
            <horizontal>
            	<samples>100</samples>
            	<resolution>1</resolution>
            	<min_angle>-2.356194</min_angle>
            	<max_angle>2.356194</max_angle>
            </horizontal>
            <vertical>
            	<samples>16</samples>
            	<resolution>1</resolution>
            	<min_angle>-0.261799</min_angle>
            	<max_angle>0.261799</max_angle>
            </vertical>
          </scan>	  
	  <range>
          	<min>0.10</min>
          	<max>20.0</max>
          	<resolution>0.001</resolution>
          </range>
	</ray>
    </sensor>
  </gazebo>
  <joint name="base_velodyne_joint" type="fixed">
    <origin rpy="0 0 0" xyz="0 0 0.5"/>
    <parent link="base_link"/>
    <child link="velodyne"/>
  </joint>

  <!--link name="base_scan">
    <inertial>
      <mass value="0.1"/>
      <origin xyz="0 0 0"/>
      <inertia ixx="0.001" ixy="0.0" ixz="0.0" iyy="0.001" iyz="0.0" izz="0.001"/>
    </inertial>
    <visual>
      <origin rpy="0 0 0" xyz="0 0 0"/>
      <geometry>
        <mesh filename="package://amr_robots_description/meshes/hokuyo/hokuyo.dae"/>
      </geometry>
    </visual>
  </link>
  <gazebo reference="base_scan">
    <sensor name="sensor_laser" type="gpu_ray">
	<visualize>0</visualize>
	<update_rate>10</update_rate>
	<pose> 0 0 0 0 0 0 </pose>
	<plugin name="ros_laser" filename="libgazebo_ros_gpu_laser.so">
          <topicName>/base_scan</topicName>
          <frameName>base_scan</frameName>
	</plugin>
	<ray>
	  <scan>
            <horizontal>
            	<samples>1000</samples>
            	<resolution>1</resolution>
            	<min_angle>-2.356194</min_angle>
            	<max_angle>2.356194</max_angle>
            </horizontal>
          </scan>	  
	  <range>
          	<min>0.10</min>
          	<max>20.0</max>
          	<resolution>0.01</resolution>
          </range>
	</ray>
    </sensor>
  </gazebo>
  <joint name="base_scan_joint" type="fixed">
    <origin rpy="0 0 0" xyz="0 0 0.33"/>
    <parent link="base_link"/>
    <child link="base_scan"/>
  </joint-->

  <joint name="hokuyo_joint" type="fixed">
    <axis xyz="0 1 0" />
    <origin xyz="0 0 0.33" rpy="0 0 0"/>
    <parent link="base_link"/>
    <child link="base_scan"/>
  </joint>

  <link name="base_scan">
    <collision>
      <origin xyz="0 0 0" rpy="0 0 0"/>
      <geometry>
        <box size="0.1 0.1 0.1"/>
      </geometry>
    </collision>
    <visual>
      <origin xyz="0 0 0" rpy="0 0 0"/>
      <geometry>
        <mesh filename="package://amr_robots_description/meshes/hokuyo/hokuyo.dae"/>
      </geometry>
    </visual>
    <inertial>
      <mass value="1e-5" />
      <origin xyz="0 0 0" rpy="0 0 0"/>
      <inertia ixx="1e-6" ixy="0" ixz="0" iyy="1e-6" iyz="0" izz="1e-6" />
    </inertial>
  </link>
  <gazebo reference="base_scan">
    <sensor type="gpu_ray" name="head_hokuyo_sensor">
      <pose>0 0 0 0 0 0</pose>
      <visualize>false</visualize>
      <update_rate>40</update_rate>
      <ray>
        <scan>
          <horizontal>
            <samples>810</samples>
            <resolution>1</resolution>
            <min_angle>-2.1</min_angle>
            <max_angle>2.1</max_angle>
          </horizontal>
        </scan>
        <range>
          <min>0.10</min>
          <max>30.0</max>
          <resolution>0.01</resolution>
        </range>
        <noise>
          <type>gaussian</type>
          <mean>0.0</mean>
          <stddev>0.01</stddev>
        </noise>
      </ray>
      <plugin name="gazebo_ros_head_hokuyo_controller" filename="libgazebo_ros_gpu_laser.so">
        <topicName>/scan</topicName>
        <frameName>base_scan</frameName>
      </plugin>
    </sensor>
  </gazebo>

  <link name="right_cam_link">
    <inertial>
      <mass value="0.1"/>
      <origin xyz="0 0 0"/>
      <inertia ixx="0.001" ixy="0.0" ixz="0.0" iyy="0.001" iyz="0.0" izz="0.001"/>
    </inertial>
    <!--visual>
      <origin rpy="0 0 0" xyz="0 0 0"/>
      <geometry>
        <mesh filename="package://amr_robots_description/meshes/xtion/asus_xtion_pro_camera.dae"/>
      </geometry>
    </visual-->
  </link>
  <gazebo reference="right_cam_link">
    <sensor name="right_camera" type="camera">
        <camera>
          <horizontal_fov>2.09</horizontal_fov>
          <image>
            <width>640</width>
            <height>480</height>
            <format>R8G8B8</format>
          </image>
          <clip>
            <near>0.1</near>
            <far>100</far>
          </clip>
        </camera>
	<pose> 0 0 0 0 0 0 </pose>
        <always_on>1</always_on>
        <update_rate>30</update_rate>
        <visualize>true</visualize>
	<plugin name='camera' filename='libgazebo_ros_camera.so'>
	<imageTopicName>/camera/right/image_raw</imageTopicName>
            <!--<CxPrime>320</CxPrime>
	    <Cx>296.7347</Cx>
	    <Cy>271.07618</Cy>
	    <focalLength>481.1358</focalLength>
	    <distortionK1>-0.39282</distortionK1>
	    <distortionK2>0.14838</distortionK2>
	    <distortionK3>-0.0058</distortionK3>
	    <distortionT1>0.00101</distortionT1>
	    <distortionT2>0.00000</distortionT2>-->
	</plugin> 
      </sensor>
  </gazebo>
  <joint name="base_rightcam_joint" type="fixed">
    <origin rpy="0 0 0" xyz="0.2 -0.1 1"/>
    <parent link="base_link"/>
    <child link="right_cam_link"/>
  </joint>

  <link name="left_cam_link">
    <inertial>
      <mass value="0.1"/>
      <origin xyz="0 0 0"/>
      <inertia ixx="0.001" ixy="0.0" ixz="0.0" iyy="0.001" iyz="0.0" izz="0.001"/>
    </inertial>
    <!--visual>
      <origin rpy="0 0 0" xyz="0 0 0"/>
      <geometry>
        <mesh filename="package://amr_robots_description/meshes/xtion/asus_xtion_pro_camera.dae"/>
      </geometry>
    </visual-->
  </link>
  <gazebo reference="left_cam_link">
    <sensor name="left_camera" type="camera">
        <camera>
          <horizontal_fov>2.09</horizontal_fov>
          <image>
            <width>640</width>
            <height>480</height>
            <format>R8G8B8</format>
          </image>
          <clip>
            <near>0.1</near>
            <far>100</far>
          </clip>
        </camera>
	<pose> 0 0 0 0 0 0 </pose>
        <always_on>1</always_on>
        <update_rate>30</update_rate>
        <visualize>true</visualize>
	<plugin name='camera' filename='libgazebo_ros_camera.so'>
	<imageTopicName>/camera/left/image_raw</imageTopicName>
            <!--<CxPrime>320</CxPrime>
	    <Cx>296.7347</Cx>
	    <Cy>271.07618</Cy>
	    <focalLength>481.1358</focalLength>
	    <distortionK1>-0.39282</distortionK1>
	    <distortionK2>0.14838</distortionK2>
	    <distortionK3>-0.0058</distortionK3>
	    <distortionT1>0.00101</distortionT1>
	    <distortionT2>0.00000</distortionT2>-->
	</plugin> 
      </sensor>
  </gazebo>
  <joint name="base_leftcam_joint" type="fixed">
    <origin rpy="0 0 0" xyz="0.2 0.1 1"/>
    <parent link="base_link"/>
    <child link="left_cam_link"/>
  </joint>
  
  <!--link name="imu_link">
    <inertial>
      <mass value="0.0001"/>
      <origin xyz="0 0 0"/>
      <inertia ixx="0.0001" ixy="0.0" ixz="0.0" iyy="0.0001" iyz="0.0" izz="0.0001"/>
    </inertial>
    <visual>
      <origin rpy="0 0 0" xyz="0 0 0"/>
      <geometry>
        <box size="0.001 0.001 0.001"/>
      </geometry>
    </visual>
  </link>
  <gazebo reference="imu_link">
    <material value="Gazebo/Grey"/>
    <sensor name='sensor_imu' type='imu'>
	<always_on>true</always_on>
	<update_rate>50.0</update_rate>
	<pose> 0 0 0 0 0 0 </pose>
	<plugin name='ros_imu' filename='libgazebo_ros_imu.so'>
          <topicName>/imu</topicName>
          <frameName>imu_link</frameName>
	</plugin> 
    </sensor>
  </gazebo-->

  <gazebo>
    <plugin name="imu_plugin" filename="libgazebo_ros_imu.so">
      <alwaysOn>true</alwaysOn>
      <bodyName>base_link</bodyName>
      <topicName>/imu</topicName>
      <gaussianNoise>0.0</gaussianNoise>
      <updateRate>50.0</updateRate>
    </plugin>
  </gazebo>

  <!--kinect camera-->
  <link name="kinect_link">
    <visual>
      <origin rpy="0 0 0" xyz="0 0 0"/>
      <geometry>
        <mesh filename="package://amr_robots_description/meshes/xtion/asus_xtion_pro_camera.dae"/>
      </geometry>
    </visual>
    <inertial>
        <mass value="0.0001" />
        <origin xyz="0 0 0" />
        <inertia ixx="0.0001" ixy="0.0" ixz="0.0"
                 iyy="0.0001" iyz="0.0" 
                 izz="0.0001" />
    </inertial>
  </link>
  <joint name="base_kinect_joint" type="fixed">
    <origin rpy="0 0 0" xyz="0.2 0.0 0.5"/>
    <parent link="base_link"/>
    <child link="kinect_link"/>
  </joint>
  <gazebo reference="kinect_link">
   <sensor type="depth" name="kinect">
    <alwaysOn>true</alwaysOn>
    <updateRate>10</updateRate>
    <camera>
          <horizontal_fov>1.57</horizontal_fov>
          <image>
            <format>R8G8B8</format>
            <width>640</width>
            <height>480</height>
          </image>
          <clip>
            <near>0.05</near>
            <far>10.0</far>
          </clip>
    </camera>
    <plugin name="kinect_controller" filename="libgazebo_ros_openni_kinect.so">
      <baseline>0.2</baseline>
      <cameraName>kinect_ir</cameraName>
      <imageTopicName>/kinect/rgb/image_raw</imageTopicName>
      <cameraInfoTopicName>/kinect/depth/camera_info</cameraInfoTopicName>
      <depthImageTopicName>/kinect/depth/image_raw</depthImageTopicName>
      <depthImageInfoTopicName>/kinect/depth/camera_info</depthImageInfoTopicName>
      <pointCloudTopicName>/kinect/depth/points</pointCloudTopicName>
      <frameName>kinect_link</frameName>
      <pointCloudCutoff>0.5</pointCloudCutoff>
      <distortionK1>0.00000001</distortionK1>
      <distortionK2>0.00000001</distortionK2>
      <distortionK3>0.00000001</distortionK3>
      <distortionT1>0.00000001</distortionT1>
      <distortionT2>0.00000001</distortionT2>
      <CxPrime>0</CxPrime>
      <Cx>0</Cx>
      <Cy>0</Cy>
      <focalLength>0</focalLength>
      <hackBaseline>0</hackBaseline>
    </plugin>
   </sensor>
  </gazebo>
  
  <!-- Front Axles + Wheels + Hubcaps -->
  <link name="p3at_front_left_axle">
    <inertial>
      <mass value="0.1"/>
      <origin xyz="0 0 0"/>
      <inertia ixx="1.0" ixy="0.0" ixz="0.0" iyy="1.0" iyz="0.0" izz="1.0"/>
    </inertial>
    <visual>
      <origin rpy="0 0 0" xyz="0 0 0"/>
      <geometry name="pioneer_geom">
        <mesh filename="package://amr_robots_description/meshes/p3at_meshes/axle.stl"/>
      </geometry>
      <material name="AxleGrey">
        <color rgba="0.5 0.5 0.5 1"/>
      </material>
    </visual>
  </link>
  <gazebo reference="p3at_front_left_axle">
    <material value="Gazebo/Grey"/>
  </gazebo>
  <joint name="base_front_left_axle_joint" type="fixed">
    <origin rpy="0 0 0" xyz="0.135 0.156 0.111"/>
    <parent link="base_link"/>
    <child link="p3at_front_left_axle"/>
  </joint>
  <link name="p3at_front_left_hub">
    <inertial>
      <mass value="0.1"/>
      <origin xyz="0 0 0"/>
      <inertia ixx="1.0" ixy="0.0" ixz="0.0" iyy="1.0" iyz="0.0" izz="1.0"/>
    </inertial>
    <visual>
      <origin rpy="0 0 0" xyz="0 0 0"/>
      <geometry name="pioneer_geom">
        <mesh filename="package://amr_robots_description/meshes/p3at_meshes/left_hubcap.stl"/>
      </geometry>
      <material name="HubcapYellow">
        <color rgba="1.0 0.811 0.151 1.0"/>
      </material>
    </visual>
  </link>
  <gazebo reference="p3at_front_left_hub">
    <material value="Gazebo/Yellow"/>
  </gazebo>
  <joint name="base_front_left_hub_joint" type="fixed">
    <origin rpy="0 0 0" xyz="0 0.041 0"/>
    <parent link="p3at_front_left_axle"/>
    <child link="p3at_front_left_hub"/>
  </joint>
  <link name="p3at_front_left_wheel">
    <inertial>
      <mass value="1.2"/>
      <!-- 1.4 kg - axle 0.1 kg - hub 0.1 kg -->
      <origin xyz="0 0 0"/>
      <inertia ixx="0.012411765597" ixy="0" ixz="0" iyy="0.015218160428" iyz="0" izz="0.011763977943"/>
    </inertial>
    <visual>
      <origin rpy="0 0 0" xyz="0 0 0"/>
      <geometry name="pioneer_geom">
        <mesh filename="package://amr_robots_description/meshes/p3at_meshes/wheel.stl"/>
      </geometry>
      <material name="WheelBlack">
        <color rgba="0.117 0.117 0.117 1"/>
      </material>
    </visual>
    <collision>
      <origin rpy="-1.57079635 0 0" xyz="0 0 0"/>
      <geometry>
        <!--mesh filename="package://amr_robots_description/meshes/p3at_meshes/wheel.stl"/-->
        <cylinder length="0.075" radius="0.111"/>
      </geometry>
    </collision>
  </link>
  <gazebo reference="p3at_front_left_wheel">
    <material value="Gazebo/Black"/>
  </gazebo>
  <joint name="p3at_front_left_wheel_joint" type="continuous">
    <axis xyz="0 1 0"/>
    <anchor xyz="0 0 0"/>
    <limit effort="100" velocity="100"/>
    <joint_properties damping="0.7"/>
    <origin rpy="0 0 0" xyz="0 0 0"/>
    <parent link="p3at_front_left_hub"/>
    <child link="p3at_front_left_wheel"/>
  </joint>
  <!-- Back Axles + Wheels + Hubcaps -->
  <link name="p3at_back_left_axle">
    <inertial>
      <mass value="0.1"/>
      <origin xyz="0 0 0"/>
      <inertia ixx="1.0" ixy="0.0" ixz="0.0" iyy="1.0" iyz="0.0" izz="1.0"/>
    </inertial>
    <visual>
      <origin rpy="0 0 0" xyz="0 0 0"/>
      <geometry name="pioneer_geom">
        <mesh filename="package://amr_robots_description/meshes/p3at_meshes/axle.stl"/>
      </geometry>
      <material name="AxleGrey">
        <color rgba="0.5 0.5 0.5 1"/>
      </material>
    </visual>
    <collision>
      <origin rpy="0 0 0" xyz="0 0 0"/>
      <geometry>
        <mesh filename="package://amr_robots_description/meshes/p3at_meshes/axle.stl"/>
      </geometry>
    </collision>
  </link>
  <gazebo reference="p3at_back_left_axle">
    <material value="Gazebo/Grey"/>
  </gazebo>
  <joint name="p3at_back_left_axle_joint" type="fixed">
    <origin rpy="0 0 0" xyz="-0.134 0.156 0.111"/>
    <parent link="base_link"/>
    <child link="p3at_back_left_axle"/>
  </joint>
  <link name="p3at_back_left_hub">
    <inertial>
      <mass value="0.1"/>
      <origin xyz="0 0 0"/>
      <inertia ixx="1.0" ixy="0.0" ixz="0.0" iyy="1.0" iyz="0.0" izz="1.0"/>
    </inertial>
    <visual>
      <origin rpy="0 0 0" xyz="0 0 0"/>
      <geometry name="pioneer_geom">
        <mesh filename="package://amr_robots_description/meshes/p3at_meshes/left_hubcap.stl"/>
      </geometry>
      <material name="HubcapYellow"/>
    </visual>
    <collision>
      <origin rpy="0 0 0" xyz="0 0 0"/>
      <geometry>
        <mesh filename="package://amr_robots_description/meshes/p3at_meshes/left_hubcap.stl"/>
      </geometry>
    </collision>
  </link>
  <gazebo reference="p3at_back_left_hub">
    <material value="Gazebo/Yellow"/>
  </gazebo>
  <joint name="p3at_back_left_hub_joint" type="fixed">
    <origin rpy="0 0 0" xyz="-0 0.041 0"/>
    <parent link="p3at_back_left_axle"/>
    <child link="p3at_back_left_hub"/>
  </joint>
  <link name="p3at_back_left_wheel">
    <inertial>
      <mass value="1.2"/>
      <origin xyz="0 0 0"/>
      <inertia ixx="0.012411765597" ixy="0" ixz="0" iyy="0.015218160428" iyz="0" izz="0.011763977943"/>
    </inertial>
    <visual>
      <origin rpy="0 0 0" xyz="0 0 0"/>
      <geometry name="pioneer_geom">
        <mesh filename="package://amr_robots_description/meshes/p3at_meshes/wheel.stl"/>
      </geometry>
      <material name="WheelBlack"/>
    </visual>
    <collision>
      <origin rpy="-1.57079635 0 0" xyz="0 0 0"/>
      <geometry>
        <!--mesh filename="package://amr_robots_description/meshes/p3at_meshes/wheel.stl"/-->
        <cylinder length="0.075" radius="0.111"/>
      </geometry>
    </collision>
  </link>
  <gazebo reference="p3at_back_left_wheel">
    <material value="Gazebo/Black"/>
  </gazebo>
  <joint name="p3at_back_left_wheel_joint" type="continuous">
    <axis xyz="0 1 0"/>
    <anchor xyz="0 0 0"/>
    <limit effort="100" velocity="100"/>
    <joint_properties damping="0.7"/>
    <origin rpy="0 0 0" xyz="0 0 0"/>
    <parent link="p3at_back_left_hub"/>
    <child link="p3at_back_left_wheel"/>
  </joint>
  <!-- see http://gazebosim.org/tutorials/?tut=ros_urdf -->
  <gazebo reference="p3at_back_left_wheel">
    <kp>1000000.0</kp>
    <!-- kp and kd for rubber -->
    <kd>100.0</kd>
    <mu1>1.0</mu1>
    <!-- was 10 -->
    <mu2>1.0</mu2>
    <!-- how to get these into <surface><friction><ode>... ?
        slip1 0.5 /slip1 
         slip2 0 /slip2 
      -->
    <!-- fdir1 0 1 0 /fdir1 -->
    <!-- see http://github.com/MobileRobots/amr-ros-config/issues/6 -->
    <maxVel>1.0</maxVel>
    <minDepth>0.00</minDepth>
    <material value="Gazebo/Black"/>
  </gazebo>
  <gazebo reference="p3at_front_left_wheel">
    <kp>1000000.0</kp>
    <!-- kp and kd for rubber -->
    <kd>100.0</kd>
    <mu1>1.0</mu1>
    <!-- was 10 -->
    <mu2>1.0</mu2>
    <!-- how to get these into <surface><friction><ode>... ?
        slip1 0.5 /slip1 
         slip2 0 /slip2 
      -->
    <!-- fdir1 0 1 0 /fdir1 -->
    <!-- see http://github.com/MobileRobots/amr-ros-config/issues/6 -->
    <maxVel>1.0</maxVel>
    <minDepth>0.00</minDepth>
    <material value="Gazebo/Black"/>
  </gazebo>
  <!-- Front Axles + Wheels + Hubcaps -->
  <link name="p3at_front_right_axle">
    <inertial>
      <mass value="0.1"/>
      <origin xyz="0 0 0"/>
      <inertia ixx="1.0" ixy="0.0" ixz="0.0" iyy="1.0" iyz="0.0" izz="1.0"/>
    </inertial>
    <visual>
      <origin rpy="0 0 0" xyz="0 0 0"/>
      <geometry name="pioneer_geom">
        <mesh filename="package://amr_robots_description/meshes/p3at_meshes/axle.stl"/>
      </geometry>
      <material name="AxleGrey">
        <color rgba="0.5 0.5 0.5 1"/>
      </material>
    </visual>
  </link>
  <gazebo reference="p3at_front_right_axle">
    <material value="Gazebo/Grey"/>
  </gazebo>
  <joint name="base_front_right_axle_joint" type="fixed">
    <origin rpy="0 0 0" xyz="0.135 -0.156 0.111"/>
    <parent link="base_link"/>
    <child link="p3at_front_right_axle"/>
  </joint>
  <link name="p3at_front_right_hub">
    <inertial>
      <mass value="0.1"/>
      <origin xyz="0 0 0"/>
      <inertia ixx="1.0" ixy="0.0" ixz="0.0" iyy="1.0" iyz="0.0" izz="1.0"/>
    </inertial>
    <visual>
      <origin rpy="0 0 0" xyz="0 0 0"/>
      <geometry name="pioneer_geom">
        <mesh filename="package://amr_robots_description/meshes/p3at_meshes/right_hubcap.stl"/>
      </geometry>
      <material name="HubcapYellow">
        <color rgba="1.0 0.811 0.151 1.0"/>
      </material>
    </visual>
  </link>
  <gazebo reference="p3at_front_right_hub">
    <material value="Gazebo/Yellow"/>
  </gazebo>
  <joint name="base_front_right_hub_joint" type="fixed">
    <origin rpy="0 0 0" xyz="0 -0.041 0"/>
    <parent link="p3at_front_right_axle"/>
    <child link="p3at_front_right_hub"/>
  </joint>
  <link name="p3at_front_right_wheel">
    <inertial>
      <mass value="1.2"/>
      <!-- 1.4 kg - axle 0.1 kg - hub 0.1 kg -->
      <origin xyz="0 0 0"/>
      <inertia ixx="0.012411765597" ixy="0" ixz="0" iyy="0.015218160428" iyz="0" izz="0.011763977943"/>
    </inertial>
    <visual>
      <origin rpy="0 0 0" xyz="0 0 0"/>
      <geometry name="pioneer_geom">
        <mesh filename="package://amr_robots_description/meshes/p3at_meshes/wheel.stl"/>
      </geometry>
      <material name="WheelBlack">
        <color rgba="0.117 0.117 0.117 1"/>
      </material>
    </visual>
    <collision>
      <origin rpy="-1.57079635 0 0" xyz="0 0 0"/>
      <geometry>
        <!--mesh filename="package://amr_robots_description/meshes/p3at_meshes/wheel.stl"/-->
        <cylinder length="0.075" radius="0.111"/>
      </geometry>
    </collision>
  </link>
  <gazebo reference="p3at_front_right_wheel">
    <material value="Gazebo/Black"/>
  </gazebo>
  <joint name="p3at_front_right_wheel_joint" type="continuous">
    <axis xyz="0 1 0"/>
    <anchor xyz="0 0 0"/>
    <limit effort="100" velocity="100"/>
    <joint_properties damping="0.7"/>
    <origin rpy="0 0 0" xyz="0 0 0"/>
    <parent link="p3at_front_right_hub"/>
    <child link="p3at_front_right_wheel"/>
  </joint>
  <!-- Back Axles + Wheels + Hubcaps -->
  <link name="p3at_back_right_axle">
    <inertial>
      <mass value="0.1"/>
      <origin xyz="0 0 0"/>
      <inertia ixx="1.0" ixy="0.0" ixz="0.0" iyy="1.0" iyz="0.0" izz="1.0"/>
    </inertial>
    <visual>
      <origin rpy="0 0 0" xyz="0 0 0"/>
      <geometry name="pioneer_geom">
        <mesh filename="package://amr_robots_description/meshes/p3at_meshes/axle.stl"/>
      </geometry>
      <material name="AxleGrey">
        <color rgba="0.5 0.5 0.5 1"/>
      </material>
    </visual>
    <collision>
      <origin rpy="0 0 0" xyz="0 0 0"/>
      <geometry>
        <mesh filename="package://amr_robots_description/meshes/p3at_meshes/axle.stl"/>
      </geometry>
    </collision>
  </link>
  <gazebo reference="p3at_back_right_axle">
    <material value="Gazebo/Grey"/>
  </gazebo>
  <joint name="p3at_back_right_axle_joint" type="fixed">
    <origin rpy="0 0 0" xyz="-0.134 -0.156 0.111"/>
    <parent link="base_link"/>
    <child link="p3at_back_right_axle"/>
  </joint>
  <link name="p3at_back_right_hub">
    <inertial>
      <mass value="0.1"/>
      <origin xyz="0 0 0"/>
      <inertia ixx="1.0" ixy="0.0" ixz="0.0" iyy="1.0" iyz="0.0" izz="1.0"/>
    </inertial>
    <visual>
      <origin rpy="0 0 0" xyz="0 0 0"/>
      <geometry name="pioneer_geom">
        <mesh filename="package://amr_robots_description/meshes/p3at_meshes/right_hubcap.stl"/>
      </geometry>
      <material name="HubcapYellow"/>
    </visual>
    <collision>
      <origin rpy="0 0 0" xyz="0 0 0"/>
      <geometry>
        <mesh filename="package://amr_robots_description/meshes/p3at_meshes/right_hubcap.stl"/>
      </geometry>
    </collision>
  </link>
  <gazebo reference="p3at_back_right_hub">
    <material value="Gazebo/Yellow"/>
  </gazebo>
  <joint name="p3at_back_right_hub_joint" type="fixed">
    <origin rpy="0 0 0" xyz="-0 -0.041 0"/>
    <parent link="p3at_back_right_axle"/>
    <child link="p3at_back_right_hub"/>
  </joint>
  <link name="p3at_back_right_wheel">
    <inertial>
      <mass value="1.2"/>
      <origin xyz="0 0 0"/>
      <inertia ixx="0.012411765597" ixy="0" ixz="0" iyy="0.015218160428" iyz="0" izz="0.011763977943"/>
    </inertial>
    <visual>
      <origin rpy="0 0 0" xyz="0 0 0"/>
      <geometry name="pioneer_geom">
        <mesh filename="package://amr_robots_description/meshes/p3at_meshes/wheel.stl"/>
      </geometry>
      <material name="WheelBlack"/>
    </visual>
    <collision>
      <origin rpy="-1.57079635 0 0" xyz="0 0 0"/>
      <geometry>
        <!--mesh filename="package://amr_robots_description/meshes/p3at_meshes/wheel.stl"/-->
        <cylinder length="0.075" radius="0.111"/>
      </geometry>
    </collision>
  </link>
  <gazebo reference="p3at_back_right_wheel">
    <material value="Gazebo/Black"/>
  </gazebo>
  <joint name="p3at_back_right_wheel_joint" type="continuous">
    <axis xyz="0 1 0"/>
    <anchor xyz="0 0 0"/>
    <limit effort="100" velocity="100"/>
    <joint_properties damping="0.7"/>
    <origin rpy="0 0 0" xyz="0 0 0"/>
    <parent link="p3at_back_right_hub"/>
    <child link="p3at_back_right_wheel"/>
  </joint>
  <!-- see http://gazebosim.org/tutorials/?tut=ros_urdf -->
  <gazebo reference="p3at_back_right_wheel">
    <kp>1000000.0</kp>
    <!-- kp and kd for rubber -->
    <kd>100.0</kd>
    <mu1>1.0</mu1>
    <!-- was 10 -->
    <mu2>1.0</mu2>
    <!-- how to get these into <surface><friction><ode>... ?
        slip1 0.5 /slip1 
         slip2 0 /slip2 
      -->
    <!-- fdir1 0 1 0 /fdir1 -->
    <!-- see http://github.com/MobileRobots/amr-ros-config/issues/6 -->
    <maxVel>1.0</maxVel>
    <minDepth>0.00</minDepth>
    <material value="Gazebo/Black"/>
  </gazebo>
  <gazebo reference="p3at_front_right_wheel">
    <kp>1000000.0</kp>
    <!-- kp and kd for rubber -->
    <kd>100.0</kd>
    <mu1>1.0</mu1>
    <!-- was 10 -->
    <mu2>1.0</mu2>
    <!-- how to get these into <surface><friction><ode>... ?
        slip1 0.5 /slip1 
         slip2 0 /slip2 
      -->
    <!-- fdir1 0 1 0 /fdir1 -->
    <!-- see http://github.com/MobileRobots/amr-ros-config/issues/6 -->
    <maxVel>1.0</maxVel>
    <minDepth>0.00</minDepth>
    <material value="Gazebo/Black"/>
  </gazebo>
  <gazebo>
    <plugin filename="libgazebo_ros_skid_steer_drive.so" name="skid_steer_drive_controller">
      <updateRate>100.0</updateRate>
      <robotNamespace>sim_p3at</robotNamespace>
      <leftFrontJoint>p3at_front_left_wheel_joint</leftFrontJoint>
      <rightFrontJoint>p3at_front_right_wheel_joint</rightFrontJoint>
      <leftRearJoint>p3at_back_left_wheel_joint</leftRearJoint>
      <rightRearJoint>p3at_back_right_wheel_joint</rightRearJoint>
      <wheelSeparation>0.4</wheelSeparation>
      <wheelDiameter>0.215</wheelDiameter>
      <robotBaseFrame>base_link</robotBaseFrame>
      <MaxForce>5.0</MaxForce>
      <torque>200</torque>
      <commandTopic>cmd_vel</commandTopic>
      <odometryTopic>odom</odometryTopic>
      <odometryFrame>odom</odometryFrame>
      <broadcastTF>1</broadcastTF>
    </plugin>
  </gazebo>
</robot>

